<?xml version="1.0"?>
<robot name="robot">
 
  <link name="robot_footprint">
  </link> 

  <link name="base_link">
    <origin xyz="0 0 0" rpy=" 0 -0 0"/>
    <visual>
      <geometry>
       <mesh filename="package://faby_sim/meshes/base_link.stl"/>
      </geometry>
      <origin rpy="0 0 0" xyz="0 0 0"/> 
    </visual>
    <collision>
      <geometry>
       <mesh filename="package://faby_sim/meshes/base_link.stl"/>
      </geometry>
      <origin rpy="0 0 0" xyz="0 0 0"/> 
    </collision>
    <inertial>
      <mass value="100"/>
      <inertia ixx="0.166667" ixy="0.0" ixz="0.0" iyy="0.166667" iyz="0.0" izz="0.166667"/>
      <origin rpy="0 0 0" xyz="0 0 0"/>
    </inertial>
  </link>
 
 <link name="front_left_wheel">
    <visual>
      <geometry>
      <cylinder length="0.05" radius="0.05"/>
      </geometry>
      <origin rpy="1.5707 0 0" xyz="0 0 0"/> 
    </visual>
    <collision>
      <geometry>
      <cylinder length="0.05" radius="0.05"/>
      </geometry>
      <origin rpy="1.5707 0 0" xyz="0 0 0"/> 
    </collision>
    <inertial>
      <mass value="5"/>
      <inertia ixx="0.14" ixy="0.0" ixz="0.0" iyy="0.14" iyz="0.0" izz="0.12"/>
      <origin rpy="1.5707 0 0" xyz="0 0 0"/> 
    </inertial>
 </link>

 <link name="front_right_wheel">
    <visual>
      <geometry>
      <cylinder length="0.05" radius="0.05"/>
      </geometry>
      <origin rpy="1.5707 0 0" xyz="0 0 0"/> 
    </visual>
    <collision>
      <geometry>
      <cylinder length="0.05" radius="0.05"/>
      </geometry>
      <origin rpy="1.5707 0 0" xyz="0 0 0"/> 
    </collision>
    <inertial>
      <mass value="5"/>
      <inertia ixx="0.14" ixy="0.0" ixz="0.0" iyy="0.14" iyz="0.0" izz="0.12"/>
      <origin rpy="1.5707 0 0" xyz="0 0 0"/> 
    </inertial>
 </link>
 
 <link name="back_left_wheel">
    <visual>
      <geometry>
      <cylinder length="0.05" radius="0.05"/>
      </geometry>
      <origin rpy="1.5707 0 0" xyz="0 0 0"/> 
    </visual>
    <collision>
      <geometry>
      <cylinder length="0.05" radius="0.05"/>
      </geometry>
      <origin rpy="1.5707 0 0" xyz="0 0 0"/> 
    </collision>
    <inertial>
      <mass value="5"/>
      <inertia ixx="0.14" ixy="0.0" ixz="0.0" iyy="0.14" iyz="0.0" izz="0.12"/>
      <origin rpy="1.5707 0 0" xyz="0 0 0"/> 
    </inertial>
 </link>

 <link name="back_right_wheel">
    <visual>
      <geometry>
      <cylinder length="0.05" radius="0.05"/>
      </geometry>
      <origin rpy="1.5707 0 0" xyz="0 0 0"/> 
    </visual>
    <collision>
      <geometry>
      <cylinder length="0.05" radius="0.05"/>
      </geometry>
      <origin rpy="1.5707 0 0" xyz="0 0 0"/> 
    </collision>
    <inertial>
      <mass value="5"/>
      <inertia ixx="0.14" ixy="0.0" ixz="0.0" iyy="0.14" iyz="0.0" izz="0.12"/>
      <origin rpy="1.5707 0 0" xyz="0 0 0"/> 
    </inertial>
 </link>

 <joint name="robot_footprint_joint" type="fixed">
    <parent link="robot_footprint"/>
    <child link="base_link"/>
    <origin xyz="0 0 0" rpy="0 0 0" />
 </joint>

 <joint name="front_left_wheel_joint" type="continuous">
    <parent link="base_link"/>
    <child link="front_left_wheel"/>
    <origin rpy="0 0 0" xyz="0.175 0.175 0.05"/>
    <axis rpy="0 0 0" xyz="0 1 0"/>
    <dynamics damping="1.0" friction="1.0"/>
    <limit effort="10000" velocity="1000"/>
 </joint>
  
 <joint name="front_right_wheel_joint" type="continuous">
    <parent link="base_link"/>
    <child link="front_right_wheel"/>
    <origin rpy="0 0 0" xyz="0.175 -0.175 0.05"/>
    <axis rpy="0 0 0" xyz="0 1 0"/>
    <dynamics damping="1.0" friction="1.0"/>
    <limit effort="10000" velocity="1000"/>
 </joint>

 <joint name="back_left_wheel_joint" type="continuous">
    <parent link="base_link"/>
    <child link="back_left_wheel"/>
    <origin rpy="0 0 0" xyz="-0.175 0.175 0.05"/>
    <axis rpy="0 0 0" xyz="0 1 0"/>
    <dynamics damping="1.0" friction="1.0"/>
    <limit effort="10000" velocity="1000"/>
 </joint>

 <joint name="back_right_wheel_joint" type="continuous">
    <parent link="base_link"/>
    <child link="back_right_wheel"/>
    <origin rpy="0 0 0" xyz="-0.175 -0.175 0.05"/>
    <axis rpy="0 0 0" xyz="0 1 0"/>
    <dynamics damping="1.0" friction="1.0"/>
    <limit effort="10000" velocity="1000"/>
 </joint>

 <!-- Teleop Controller -->
  
  <!-- <gazebo>
   <plugin name="skid_steer_drive_controller" filename="libgazebo_ros_skid_steer_drive.so">
    <updateRate>100.0</updateRate>
    <robotNamespace>/</robotNamespace>
    <leftFrontJoint>front_left_wheel_joint</leftFrontJoint>
    <rightFrontJoint>front_right_wheel_joint</rightFrontJoint>
    <leftRearJoint>back_left_wheel_joint</leftRearJoint>
    <rightRearJoint>back_right_wheel_joint</rightRearJoint>
    <wheelSeparation>0.5</wheelSeparation>
    <wheelDiameter>0.1</wheelDiameter>
    <robotBaseFrame>parent_link</robotBaseFrame>
    <torque>5</torque>
    <topicName>cmd_vel</topicName>
    <broadcastTF>false</broadcastTF>
   </plugin>
  </gazebo> -->

  <gazebo>
   <plugin name="omni_steer_drive_controller" filename="libgazebo_ros_planar_move.so">
      <commandTopic>cmd_vel</commandTopic>
      <odometryTopic>odom</odometryTopic>
      <odometryFrame>odom</odometryFrame>
      <odometryRate>20.0</odometryRate>
      <robotBaseFrame>robot_footprint</robotBaseFrame>
    </plugin>
  </gazebo>

 <!-- Camera Link -->
  <link name="camera_link">
    <collision>
      <origin xyz="0 0 0" rpy="0 0 0"/>
      <geometry>
       <mesh filename="package://faby_sim/meshes/camera_link.stl"/>
      </geometry>
    </collision>
    <visual>
      <origin xyz="0 0 0" rpy="0 0 0"/>
      <geometry>
       <mesh filename="package://faby_sim/meshes/camera_link.stl"/>
      </geometry>
    </visual>
    <inertial>
      <mass value="1e-5" />
      <origin xyz="0 0 0" rpy="0 0 0"/>
      <inertia ixx="1e-6" ixy="0" ixz="0" iyy="1e-6" iyz="0" izz="1e-6" />
    </inertial>
  </link>
   
  <joint name="camera_joint" type="fixed">
    <parent link="base_link"/>
    <child link="camera_link"/>
    <axis xyz="0 0 0" />
    <origin xyz="0.04 0 1.457" rpy="0 0 0"/>
  </joint>
  
  <!-- Camera Plugin-->
  <gazebo reference="camera_link">
    <sensor type="camera" name="camera1">
      <update_rate>30.0</update_rate>
      <camera name="head">
        <horizontal_fov>1.3962634</horizontal_fov>
        <image>
          <width>800</width>
          <height>800</height>
          <format>R8G8B8</format>
        </image>
        <clip>
          <near>0.02</near>
          <far>300</far>
        </clip>
        <noise>
          <type>gaussian</type>
          <!-- Noise is sampled independently per pixel on each frame.
               That pixel's noise value is added to each of its color
               channels, which at that point lie in the range [0,1]. -->
          <mean>0.0</mean>
          <stddev>0.007</stddev>
        </noise>
      </camera>
      <plugin name="camera_controller" filename="libgazebo_ros_camera.so">
        <alwaysOn>true</alwaysOn>
        <updateRate>0.0</updateRate>
        <cameraName>faby/camera</cameraName>
        <imageTopicName>faby/image_raw</imageTopicName>
        <cameraInfoTopicName>faby/camera_info</cameraInfoTopicName>
        <frameName>camera_link</frameName>
        <hackBaseline>0.07</hackBaseline>
        <distortionK1>0.0</distortionK1>
        <distortionK2>0.0</distortionK2>
        <distortionK3>0.0</distortionK3>
        <distortionT1>0.0</distortionT1>
        <distortionT2>0.0</distortionT2>
      </plugin>
    </sensor>
  </gazebo>
  
 <!-- Depth Camera Intel RealSense D435i -->
  <link name="realsense_link">
    <collision>
      <origin xyz="0 0 0" rpy="0 0 0"/>
      <geometry>
       <mesh filename="package://faby_sim/meshes/realsense_link.stl"/>
      </geometry>
    </collision>
    <visual>
      <origin xyz="0 0 0" rpy="0 0 0"/>
      <geometry>
       <mesh filename="package://faby_sim/meshes/realsense_link.stl"/>
      </geometry>
    </visual>
    <inertial>
      <mass value="1e-5" />
      <origin xyz="0 0 0" rpy="0 0 0"/>
      <inertia ixx="1e-6" ixy="0" ixz="0" iyy="1e-6" iyz="0" izz="1e-6" />
    </inertial>
  </link>
   
  <joint name="realsense_joint" type="fixed">
    <parent link="base_link"/>
    <child link="realsense_link"/>
    <axis xyz="0 0 0" />
    <origin xyz="0.14 0 0.675" rpy="0 0 0"/>
  </joint>
  <joint name="realsense_optical_joint" type="fixed">
    <origin xyz="0 0 0" rpy="-1.5707 0 -1.5707"/>
    <parent link="realsense_link"/>
    <child link="realsense_optical_link"/>
  </joint>
  <link name="realsense_optical_link"/>
  
  <gazebo reference="realsense_link">
   <sensor name="realsense" type="depth">
    <update_rate>20</update_rate>
    <camera>
     <!-- <pose>0 0 0 0 1.5707 0</pose> -->
      <horizontal_fov>1.047198</horizontal_fov>
      <image>
        <width>640</width>
        <height>480</height>
        <format>R8G8B8</format>
      </image>
      <clip>
        <near>0.05</near>
        <far>3</far>
      </clip>
    </camera>
    <plugin name="realsense_controller" filename="libgazebo_ros_openni_kinect.so">
      <baseline>0.2</baseline>
      <alwaysOn>true</alwaysOn>
      <updateRate>1.0</updateRate>
      <cameraName>realsense_ir</cameraName>
      <imageTopicName>/realsense/color/image_raw</imageTopicName>
      <cameraInfoTopicName>/realsense/color/camera_info</cameraInfoTopicName>
      <depthImageTopicName>/realsense/depth/image_raw</depthImageTopicName>
      <depthImageInfoTopicName>/realsense/depth/camera_info</depthImageInfoTopicName>
      <pointCloudTopicName>/realsense/depth/points</pointCloudTopicName>
      <frameName>realsense_optical_link</frameName>
      <pointCloudCutoff>0.5</pointCloudCutoff>
      <pointCloudCutoffMax>3.0</pointCloudCutoffMax>
      <distortionK1>0.00000001</distortionK1>
      <distortionK2>0.00000001</distortionK2>
      <distortionK3>0.00000001</distortionK3>
      <distortionT1>0.00000001</distortionT1>
      <distortionT2>0.00000001</distortionT2>
      <CxPrime>0</CxPrime>
      <Cx>0</Cx>
      <Cy>0</Cy>
      <focalLength>0</focalLength>
      <hackBaseline>0</hackBaseline>
    </plugin>
   </sensor>
  </gazebo>

 <!-- IMU link -->
  <link name="imu_link">
    <origin xyz="0 0 0" rpy=" 0 -0 0"/>
    <visual>
      <geometry>
       <box size="0.05 0.05 0.02"/>
      </geometry>
      <origin rpy="0 0 0" xyz="0 0 0"/> 
    </visual>
    <collision>
      <geometry>
       <box size="0.05 0.05 0.05"/>
      </geometry>
      <origin rpy="0 0 0" xyz="0 0 0"/>  
    </collision>
    <inertial>
      <mass value="10"/>
      <inertia ixx="0.166667" ixy="0.0" ixz="0.0" iyy="0.166667" iyz="0.0" izz="0.166667"/>
      <origin rpy="0 0 0" xyz="0 0 0.05"/>
    </inertial>
  </link>

  <joint name="imu_joint" type="fixed">
    <parent link="base_link"/>
    <child link="imu_link"/>
    <axis xyz="0 0 0" />
    <origin xyz="0 0 0.2" rpy="0 0 0"/>
  </joint>
  <!-- IMU Plugin -->
  <gazebo reference="imu_link">
    <gravity>true</gravity>
    <sensor name="imu_sensor" type="imu">
      <always_on>true</always_on>
      <update_rate>100</update_rate>
      <visualize>true</visualize>
      <topic>__default_topic__</topic>
      <plugin filename="libgazebo_ros_imu_sensor.so" name="imu_plugin">
        <topicName>imu</topicName>
        <bodyName>imu_link</bodyName>
        <updateRateHZ>10.0</updateRateHZ>
        <gaussianNoise>0.0</gaussianNoise>
        <xyzOffset>0 0 0</xyzOffset>
        <rpyOffset>0 0 0</rpyOffset>
        <frameName>imu_link</frameName>
        <initialOrientationAsReference>false</initialOrientationAsReference>
      </plugin>
      <pose>0 0 0 0 0 0</pose>
    </sensor>
  </gazebo>
  
  <gazebo reference="base_link">
   <material>Gazebo/Blue</material>
  </gazebo>
 <gazebo reference="robot_footprint">
  <gravity>true</gravity>
 </gazebo>
 
</robot>
